<?xml version="1.0"?>

<!-- to run rviz - ros2 launch urdf_tutorial display.launch.py model:=/home/maksim/Templates/new_arm_ws/src/arduinobot_description/urdf/arduinobot.urdf.xacro  -->
<robot xmlns:xacro="https://www.ros.org/wiki/xacro" name="arduinobot">
    
    <!-- Variables -->
    <xacro:property name="PI" value="3.14159" />
    <xacro:property name="effort" value="30.0" />
    <xacro:property name="velocity" value="10.0" />

    <link name="world" />

    <link name="base_link">
        <visual>
            <!-- Orientation and position only for mesh -->
            <origin rpy="0 0 0"  xyz="-0.5 -0.5 0" />
            <geometry>
                <mesh filename="package://arduinobot_description/meshes/basement.STL" scale="0.01 0.01 0.01" />
            </geometry>
        </visual>
    </link>

    <link name="base_plate">
        <visual>
            <origin rpy="0 0 0"  xyz="-0.39 -0.39 -0.56" />
            <geometry>
                <mesh filename="package://arduinobot_description/meshes/base_plate.STL" scale="0.01 0.01 0.01" />
            </geometry>
        </visual>
    </link>

    <!-- JOINTS STATE -->
    <!-- We linked two links - world with base link  -->
    <joint name="virtual_joint" type="fixed">
        <parent link="world" />
        <child link="base_link" />
        <!-- Orientation and position for joint  -->
        <origin rpy="0 0 0" xyz="0 0 0" />
    </joint>

    <joint name="joint_1" type="revolute">
        <parent link="base_link" />
        <child link="base_plate" />
        <axis xyz="0 0 1" />
        <origin rpy="0 0 0" xyz="0 0 0.307" />
        <limit lower="-${PI/2}" upper="${PI/2}" effort="${effort}" velocity="${velocity}" />
    </joint>
</robot>